Workbook

Sheet シート1
B1: 001 | C1: 002
A2: notes | B2: 51334422112 | C2: #NUM! | D2: #NUM! | E2: 51334422112 | F2: #NUM! | G2: #NUM!
A3: score | B3: 000000 | C3: 0000001 | D3: 0000002 | E3: 0000003 | F3: 0000004 | G3: 0000005
A4: ranking1 | B4: 0
A5: ranking2 | B5: 0
A6: ranking3 | B6: 0
A7: ranking4 | B7: 0
A8: ranking5 | B8: 0
A10: 1左2右3上4下5なし
A12: json
A13: 0上1下2左3右

Sheet Charts

Sheet Test
A1: 46038.443 | B1: UP
A2: 46038.443 | B2: DOWN
A3: 46038.443 | B3: LEFT
A4: 46038.446 | B4: UP
A5: 46038.446 | B5: DOWN
A6: 46038.446 | B6: LEFT
A7: 46038.446 | B7: RIGHT
A8: 46038.447 | B8: UP
A9: 46038.447 | B9: DOWN
A10: 46038.447 | B10: LEFT
A11: 46038.447 | B11: RIGHT
A12: 46038.448 | B12: UP
... A15: 46038.448 | B15: RIGHT
A16: 46038.452 | B16: UP | C16: FALSE
A17: 46038.452 | B17: DOWN | C17: OK
A18: 46038.452 | B18: LEFT | C18: OK
A19: 46038.452 | B19: RIGHT | C19: FALSE
A20: 46038.453 | B20: UP | C20: FALSE
A21: 46038.453 | B21: DOWN | C21: FALSE
A22: 46038.454 | B22: RIGHT | C22: OK
A23: 46038.454 | B23: UP | C23: FALSE
A24: 46038.454 | B24: DOWN | C24: FALSE
A25: 46038.454 | B25: LEFT | C25: FALSE
A26: 46038.454 | B26: RIGHT | C26: FALSE
A27: 46038.454 | B27: UP | C27: OK
A28: 46038.454 | B28: DOWN | C28: OK
A29: 46038.454 | B29: LEFT | C29: OK
A30: 46038.454 | B30: RIGHT | C30: OK
A31: 46038.457 | B31: UP | C31: FALSE
A32: 46038.457 | B32: DOWN | C32: FALSE
A33: 46038.457 | B33: LEFT | C33: FALSE
A34: 46038.457 | B34: RIGHT | C34: FALSE
A35: 46038.46 | B35: UP | C35: OK
A36: 46038.46 | B36: DOWN | C36: NG
A37: 46038.46 | B37: LEFT | C37: NG
A38: 46038.46 | B38: RIGHT | C38: NG
A39: 46038.461 | B39: UP | C39: OK
A40: 46038.461 | B40: DOWN | C40: OK
A41: 46038.461 | B41: LEFT | C41: OK
A42: 46038.461 | B42: RIGHT | C42: NG
...

Sheet Sessions
A1: sessionID | B1: Player name | C1: score | D1: date | E1: status
A2: sess_1765788380367_z31uy6 | B2: web_player | C2: song_01 | D2: 46006.741 | E2: started
A3: sess_1765788402256_eg2dna | B3: web_player | C3: song_01 | D3: 46006.741 | E3: started
A4: sess_1765788403129_iikuxg | B4: web_player | C4: song_01 | D4: 46006.741 | E4: started
A5: sess_1765788611524_wfvahi | B5: web_player | C5: song_01 | D5: 46006.743 | E5: started
A6: sess_1765788918655_7xsy27 | B6: web_player | C6: song_01 | D6: 46006.747 | E6: started
A7: sess_1765788921635_dthrlg | B7: web_player | C7: song_01 | D7: 46006.747 | E7: started
A8: sess_1765789859046_wvt7im | B8: web_player | C8: song_01 | D8: 46006.758 | E8: started
A9: sess_1765790404389_dgaonl | B9: web_player | C9: song_01 | D9: 46006.764 | E9: started
A10: sess_1765790406651_hf28b3 | B10: web_player | C10: song_01 | D10: 46006.764 | E10: started
A11: sess_1765790469774_ltpymf | B11: web_player | C11: song_01 | D11: 46006.765 | E11: started
A12: sess_1765790569129_tgyf2m | B12: web_player | C12: song_01 | D12: 46006.766 | E12: started
A13: sess_1765790569609_hspuru | B13: web_player | C13: song_01 | D13: 46006.766 | E13: started
... A208: sess_1769420706667 | B208: Player | C208: song_01 | D208: 46048.781 | E208: submitted

Sheet Scores
A1: name | B1: radetukey
A2: maxBlock | B2: 4 | D2: time(ms) = offset + num * (60000 / BPM / LPB)
A3: BPM | B3: 110
A4: offset | D4: 0
A5: notes↓
A6: LPB | B6: 24 | C6: num | D6: 550 | E6: block | F6: 2 | G6: type | H6: 1 | I6: comment | J6: 出だし | K6: time(変換後) | L6: =$B$4+(D6-300)*(60000/$B$3/$B$6) -> 5681.8182
A7: LPB | B7: 24 | C7: num | D7: 574 | E7: block | F7: 3 | G7: type | H7: 1 | I7: comment | K7: time(変換後) | L7: =$B$4+(D7-300)*(60000/$B$3/$B$6) -> 6227.2727
A8: LPB | B8: 24 | C8: num | D8: 592 | E8: block | F8: 2 | G8: type | H8: 1 | I8: comment | K8: time(変換後) | L8: =$B$4+(D8-300)*(60000/$B$3/$B$6) -> 6636.3636
A9: LPB | B9: 24 | C9: num | D9: 640 | E9: block | F9: 3 | G9: type | H9: 1 | I9: comment | K9: time(変換後) | L9: =$B$4+(D9-300)*(60000/$B$3/$B$6) -> 7727.2727
A10: LPB | B10: 24 | C10: num | D10: 660 | E10: block | F10: 2 | G10: type | H10: 1 | I10: comment | K10: time(変換後) | L10: =$B$4+(D10-300)*(60000/$B$3/$B$6) -> 8181.8182
A11: LPB | B11: 24 | C11: num | D11: 680 | E11: block | F11: 3 | G11: type | H11: 1 | I11: comment | K11: time(変換後) | L11: =$B$4+(D11-300)*(60000/$B$3/$B$6) -> 8636.3636
A12: LPB | B12: 24 | C12: num | D12: 723 | E12: block | F12: 2 | G12: type | H12: 1 | I12: comment | J12: A1-1 | K12: time(変換後) | L12: =$B$4+(D12-300)*(60000/$B$3/$B$6) -> 9613.6364
A13: LPB | B13: 24 | C13: num | D13: 770 | E13: block | F13: 3 | G13: type | H13: 1 | I13: comment | K13: time(変換後) | L13: =$B$4+(D13-300)*(60000/$B$3/$B$6) -> 10681.818
A14: LPB | B14: 24 | C14: num | D14: 808 | E14: block | F14: 2 | G14: type | H14: 1 | I14: comment | K14: time(変換後) | L14: =$B$4+(D14-300)*(60000/$B$3/$B$6) -> 11545.455
A15: LPB | B15: 24 | C15: num | D15: 850 | E15: block | F15: 3 | G15: type | H15: 1 | I15: comment | K15: time(変換後) | L15: =$B$4+(D15-300)*(60000/$B$3/$B$6) -> 12500
A16: LPB | B16: 24 | C16: num | D16: 893 | E16: block | F16: 2 | G16: type | H16: 1 | I16: comment | K16: time(変換後) | L16: =$B$4+(D16-300)*(60000/$B$3/$B$6) -> 13477.273
A17: LPB | B17: 24 | C17: num | D17: 930 | E17: block | F17: 3 | G17: type | H17: 1 | I17: comment | K17: time(変換後) | L17: =$B$4+(D17-300)*(60000/$B$3/$B$6) -> 14318.182
A18: LPB | B18: 24 | C18: num | D18: 976 | E18: block | F18: 2 | G18: type | H18: 1 | I18: comment | K18: time(変換後) | L18: =$B$4+(D18-300)*(60000/$B$3/$B$6) -> 15363.636
A19: LPB | B19: 24 | C19: num | D19: 1015 | E19: block | F19: 3 | G19: type | H19: 1 | I19: comment | K19: time(変換後) | L19: =$B$4+(D19-300)*(60000/$B$3/$B$6) -> 16250
A20: LPB | B20: 24 | C20: num | D20: 1058 | E20: block | F20: 2 | G20: type | H20: 1 | I20: comment | K20: time(変換後) | L20: =$B$4+(D20-300)*(60000/$B$3/$B$6) -> 17227.273
A21: LPB | B21: 24 | C21: num | D21: 1081 | E21: block | F21: 3 | G21: type | H21: 1 | I21: comment | K21: time(変換後) | L21: =$B$4+(D21-300)*(60000/$B$3/$B$6) -> 17750
A22: LPB | B22: 24 | C22: num | D22: 1100 | E22: block | F22: 2 | G22: type | H22: 1 | I22: comment | K22: time(変換後) | L22: =$B$4+(D22-300)*(60000/$B$3/$B$6) -> 18181.818
A23: LPB | B23: 24 | C23: num | D23: 1141 | E23: block | F23: 3 | G23: type | H23: 1 | I23: comment | K23: time(変換後) | L23: =$B$4+(D23-300)*(60000/$B$3/$B$6) -> 19113.636
A24: LPB | B24: 24 | C24: num | D24: 1163 | E24: block | F24: 2 | G24: type | H24: 1 | I24: comment | K24: time(変換後) | L24: =$B$4+(D24-300)*(60000/$B$3/$B$6) -> 19613.636
... A30: LPB | B30: 24 | C30: num | D30: 1347 | E30: block | F30: 2 | G30: type | H30: 1 | I30: comment | K30: time(変換後) | L30: =$B$4+(D30-300)*(60000/$B$3/$B$6) -> 23795.455
A31: LPB | B31: 24 | C31: num | D31: 1392 | E31: block | F31: 0 | G31: type | H31: 1 | I31: comment | J31: A1-2 | K31: time(変換後) | L31: =$B$4+(D31-300)*(60000/$B$3/$B$6) -> 24818.182
A32: LPB | B32: 24 | C32: num | D32: 1416 | E32: block | F32: 1 | G32: type | H32: 1 | I32: comment | K32: time(変換後) | L32: =$B$4+(D32-300)*(60000/$B$3/$B$6) -> 25363.636
A33: LPB | B33: 24 | C33: num | D33: 1435 | E33: block | F33: 0 | G33: type | H33: 1 | I33: comment | K33: time(変換後) | L33: =$B$4+(D33-300)*(60000/$B$3/$B$6) -> 25795.455
A34: LPB | B34: 24 | C34: num | D34: 1474 | E34: block | F34: 1 | G34: type | H34: 1 | I34: comment | K34: time(変換後) | L34: =$B$4+(D34-300)*(60000/$B$3/$B$6) -> 26681.818
A35: LPB | B35: 24 | C35: num | D35: 1492 | E35: block | F35: 0 | G35: type | H35: 1 | I35: comment | K35: time(変換後) | L35: =$B$4+(D35-300)*(60000/$B$3/$B$6) -> 27090.909
A36: LPB | B36: 24 | C36: num | D36: 1513 | E36: block | F36: 1 | G36: type | H36: 1 | I36: comment | K36: time(変換後) | L36: =$B$4+(D36-300)*(60000/$B$3/$B$6) -> 27568.182
A37: LPB | B37: 24 | C37: num | D37: 1557 | E37: block | F37: 0 | G37: type | H37: 1 | I37: comment | K37: time(変換後) | L37: =$B$4+(D37-300)*(60000/$B$3/$B$6) -> 28568.182
A38: LPB | B38: 24 | C38: num | D38: 1603 | E38: block | F38: 1 | G38: type | H38: 1 | I38: comment | K38: time(変換後) | L38: =$B$4+(D38-300)*(60000/$B$3/$B$6) -> 29613.636
A39: LPB | B39: 24 | C39: num | D39: 1645 | E39: block | F39: 0 | G39: type | H39: 1 | I39: comment | K39: time(変換後) | L39: =$B$4+(D39-300)*(60000/$B$3/$B$6) -> 30568.182
A40: LPB | B40: 24 | C40: num | D40: 1683 | E40: block | F40: 1 | G40: type | H40: 1 | I40: comment | K40: time(変換後) | L40: =$B$4+(D40-300)*(60000/$B$3/$B$6) -> 31431.818
A41: LPB | B41: 24 | C41: num | D41: 1725 | E41: block | F41: 0 | G41: type | H41: 1 | I41: comment | K41: time(変換後) | L41: =$B$4+(D41-300)*(60000/$B$3/$B$6) -> 32386.364
A42: LPB | B42: 24 | C42: num | D42: 1775 | E42: block | F42: 1 | G42: type | H42: 1 | I42: comment | K42: time(変換後) | L42: =$B$4+(D42-300)*(60000/$B$3/$B$6) -> 33522.727
A43: LPB | B43: 24 | C43: num | D43: 1817 | E43: block | F43: 0 | G43: type | H43: 1 | I43: comment | K43: time(変換後) | L43: =$B$4+(D43-300)*(60000/$B$3/$B$6) -> 34477.273
... A49: LPB | B49: 24 | C49: num | D49: 1971 | E49: block | F49: 0 | G49: type | H49: 1 | I49: comment | K49: time(変換後) | L49: =$B$4+(D49-300)*(60000/$B$3/$B$6) -> 37977.273
A50: LPB | B50: 24 | C50: num | D50: 2053 | E50: block | F50: 2 | G50: type | H50: 1 | I50: comment | J50: A1-3 | K50: time(変換後) | L50: =$B$4+(D50-300)*(60000/$B$3/$B$6) -> 39840.909
...

Sheet Rankings
A1: name | B1: result
A2: staff1 | B2: 1000
A3: staff2 | B3: 500
A4: Player | B4: 381
A5: staff3 | B5: 100
A6: staff4 | B6: 50

Sheet Results
A1: date | B1: sessionID | C1: name | D1: song | E1: result
A2: 46042.741 | B2: sess_1768898748101_fwx6p2 | C2: Player | D2: song_01 | E2: 0
A3: 46047.534 | B3: sess_1769312812742_klfx3h | C3: Player | D3: song_01 | E3: 0
A4: N/A | B4: N/A | C4: staff1 | D4: song_01 | E4: 1000
A5: N/A | B5: N/A | C5: staff2 | D5: song_01 | E5: 500
A6: N/A | B6: N/A | C6: staff3 | D6: song_01 | E6: 100
A7: N/A | B7: N/A | C7: staff4 | D7: song_01 | E7: 50
A8: N/A | B8: N/A | C8: staff5 | D8: song_01 | E8: 10
A9: 46047.553 | B9: sess_1769314533506_wycbx6 | C9: Player | D9: song_01 | E9: 0
A10: 46047.557 | B10: sess_1769314865127_04ymid | C10: web_player | D10: song_01 | E10: 30
A11: 46047.56 | B11: sess_1769315019087_uldtzv | C11: anonymous | D11: song_01 | E11: 30
A12: 46047.65 | B12: sess_1769322842242 | C12: Player | D12: song_01 | E12: 0
A13: 46047.653 | B13: sess_1769323085964 | C13: Player | D13: song_01 | E13: 284
A14: 46047.654 | B14: sess_1769323218207_293poc | C14: Player | D14: song_01 | E14: 0
A15: 46047.657 | B15: sess_1769323474775 | C15: Player | D15: song_01 | E15: 0
A16: 46047.704 | B16: sess_1769327472656_ezgx4r | C16: anonymous | D16: song_01 | E16: 0
A17: 46047.709 | B17: sess_1769327997550 | C17: Player | D17: song_01 | E17: 75
A18: 46047.711 | B18: sess_1769328182360_q8arga | C18: Player | D18: song_01 | E18: 0
A19: 46047.739 | B19: sess_1769330589426 | C19: Player | D19: song_01 | E19: 0
A20: 46047.744 | B20: sess_1769330945704 | C20: Player | D20: song_01 | E20: 75
... A60: 46048.782 | B60: sess_1769420706667 | C60: Player | D60: song_01 | E60: 159

Sheet 避難用
A1: LPB | B1: 24 | C1: num | D1: 550 | E1: block | F1: 2 | G1: type | H1: 1 | I1: comment | J1: 出だし | K1: time(変換後) | L1: =Scores!$B$4+D1*(60000/Scores!$B$3/'避難用'!$B$1) -> 12500
A2: LPB | B2: 24 | C2: num | D2: 574 | E2: block | F2: 3 | G2: type | H2: 1 | I2: comment | K2: time(変換後) | L2: =Scores!$B$4+D2*(60000/Scores!$B$3/'避難用'!$B$1) -> 13045.455
A3: LPB | B3: 24 | C3: num | D3: 592 | E3: block | F3: 2 | G3: type | H3: 1 | I3: comment | K3: time(変換後) | L3: =Scores!$B$4+D3*(60000/Scores!$B$3/'避難用'!$B$1) -> 13454.545
A4: LPB | B4: 24 | C4: num | D4: 640 | E4: block | F4: 3 | G4: type | H4: 1 | I4: comment | K4: time(変換後) | L4: =Scores!$B$4+D4*(60000/Scores!$B$3/'避難用'!$B$1) -> 14545.455
A5: LPB | B5: 24 | C5: num | D5: 660 | E5: block | F5: 2 | G5: type | H5: 1 | I5: comment | K5: time(変換後) | L5: =Scores!$B$4+D5*(60000/Scores!$B$3/'避難用'!$B$1) -> 15000
A6: LPB | B6: 24 | C6: num | D6: 680 | E6: block | F6: 3 | G6: type | H6: 1 | I6: comment | K6: time(変換後) | L6: =Scores!$B$4+D6*(60000/Scores!$B$3/'避難用'!$B$1) -> 15454.545
A7: LPB | B7: 24 | C7: num | D7: 723 | E7: block | F7: 2 | G7: type | H7: 1 | I7: comment | J7: A1-1 | K7: time(変換後) | L7: =Scores!$B$4+D7*(60000/Scores!$B$3/'避難用'!$B$1) -> 16431.818
A8: LPB | B8: 24 | C8: num | D8: 770 | E8: block | F8: 3 | G8: type | H8: 1 | I8: comment | K8: time(変換後) | L8: =Scores!$B$4+D8*(60000/Scores!$B$3/'避難用'!$B$1) -> 17500
A9: LPB | B9: 24 | C9: num | D9: 808 | E9: block | F9: 2 | G9: type | H9: 1 | I9: comment | K9: time(変換後) | L9: =Scores!$B$4+D9*(60000/Scores!$B$3/'避難用'!$B$1) -> 18363.636
A10: LPB | B10: 24 | C10: num | D10: 850 | E10: block | F10: 3 | G10: type | H10: 1 | I10: comment | K10: time(変換後) | L10: =Scores!$B$4+D10*(60000/Scores!$B$3/'避難用'!$B$1) -> 19318.182
A11: LPB | B11: 24 | C11: num | D11: 893 | E11: block | F11: 2 | G11: type | H11: 1 | I11: comment | K11: time(変換後) | L11: =Scores!$B$4+D11*(60000/Scores!$B$3/'避難用'!$B$1) -> 20295.455
A12: LPB | B12: 24 | C12: num | D12: 930 | E12: block | F12: 3 | G12: type | H12: 1 | I12: comment | K12: time(変換後) | L12: =Scores!$B$4+D12*(60000/Scores!$B$3/'避難用'!$B$1) -> 21136.364
A13: LPB | B13: 24 | C13: num | D13: 976 | E13: block | F13: 2 | G13: type | H13: 1 | I13: comment | K13: time(変換後) | L13: =Scores!$B$4+D13*(60000/Scores!$B$3/'避難用'!$B$1) -> 22181.818
A14: LPB | B14: 24 | C14: num | D14: 1015 | E14: block | F14: 3 | G14: type | H14: 1 | I14: comment | K14: time(変換後) | L14: =Scores!$B$4+D14*(60000/Scores!$B$3/'避難用'!$B$1) -> 23068.182
A15: LPB | B15: 24 | C15: num | D15: 1058 | E15: block | F15: 2 | G15: type | H15: 1 | I15: comment | K15: time(変換後) | L15: =Scores!$B$4+D15*(60000/Scores!$B$3/'避難用'!$B$1) -> 24045.455
A16: LPB | B16: 24 | C16: num | D16: 1081 | E16: block | F16: 3 | G16: type | H16: 1 | I16: comment | K16: time(変換後) | L16: =Scores!$B$4+D16*(60000/Scores!$B$3/'避難用'!$B$1) -> 24568.182
A17: LPB | B17: 24 | C17: num | D17: 1100 | E17: block | F17: 2 | G17: type | H17: 1 | I17: comment | K17: time(変換後) | L17: =Scores!$B$4+D17*(60000/Scores!$B$3/'避難用'!$B$1) -> 25000
A18: LPB | B18: 24 | C18: num | D18: 1141 | E18: block | F18: 3 | G18: type | H18: 1 | I18: comment | K18: time(変換後) | L18: =Scores!$B$4+D18*(60000/Scores!$B$3/'避難用'!$B$1) -> 25931.818
A19: LPB | B19: 24 | C19: num | D19: 1163 | E19: block | F19: 2 | G19: type | H19: 1 | I19: comment | K19: time(変換後) | L19: =Scores!$B$4+D19*(60000/Scores!$B$3/'避難用'!$B$1) -> 26431.818
... A25: LPB | B25: 24 | C25: num | D25: 1347 | E25: block | F25: 2 | G25: type | H25: 1 | I25: comment | K25: time(変換後) | L25: =Scores!$B$4+D25*(60000/Scores!$B$3/'避難用'!$B$1) -> 30613.636
A26: LPB | B26: 24 | C26: num | D26: 1392 | E26: block | F26: 0 | G26: type | H26: 1 | I26: comment | J26: A1-2 | K26: time(変換後) | L26: =Scores!$B$4+D26*(60000/Scores!$B$3/'避難用'!$B$1) -> 31636.364
A27: LPB | B27: 24 | C27: num | D27: 1416 | E27: block | F27: 1 | G27: type | H27: 1 | I27: comment | K27: time(変換後) | L27: =Scores!$B$4+D27*(60000/Scores!$B$3/'避難用'!$B$1) -> 32181.818
A28: LPB | B28: 24 | C28: num | D28: 1435 | E28: block | F28: 0 | G28: type | H28: 1 | I28: comment | K28: time(変換後) | L28: =Scores!$B$4+D28*(60000/Scores!$B$3/'避難用'!$B$1) -> 32613.636
A29: LPB | B29: 24 | C29: num | D29: 1474 | E29: block | F29: 1 | G29: type | H29: 1 | I29: comment | K29: time(変換後) | L29: =Scores!$B$4+D29*(60000/Scores!$B$3/'避難用'!$B$1) -> 33500
A30: LPB | B30: 24 | C30: num | D30: 1492 | E30: block | F30: 0 | G30: type | H30: 1 | I30: comment | K30: time(変換後) | L30: =Scores!$B$4+D30*(60000/Scores!$B$3/'避難用'!$B$1) -> 33909.091
A31: LPB | B31: 24 | C31: num | D31: 1513 | E31: block | F31: 1 | G31: type | H31: 1 | I31: comment | K31: time(変換後) | L31: =Scores!$B$4+D31*(60000/Scores!$B$3/'避難用'!$B$1) -> 34386.364
A32: LPB | B32: 24 | C32: num | D32: 1557 | E32: block | F32: 0 | G32: type | H32: 1 | I32: comment | K32: time(変換後) | L32: =Scores!$B$4+D32*(60000/Scores!$B$3/'避難用'!$B$1) -> 35386.364
A33: LPB | B33: 24 | C33: num | D33: 1603 | E33: block | F33: 1 | G33: type | H33: 1 | I33: comment | K33: time(変換後) | L33: =Scores!$B$4+D33*(60000/Scores!$B$3/'避難用'!$B$1) -> 36431.818
A34: LPB | B34: 24 | C34: num | D34: 1645 | E34: block | F34: 0 | G34: type | H34: 1 | I34: comment | K34: time(変換後) | L34: =Scores!$B$4+D34*(60000/Scores!$B$3/'避難用'!$B$1) -> 37386.364
A35: LPB | B35: 24 | C35: num | D35: 1683 | E35: block | F35: 1 | G35: type | H35: 1 | I35: comment | K35: time(変換後) | L35: =Scores!$B$4+D35*(60000/Scores!$B$3/'避難用'!$B$1) -> 38250
A36: LPB | B36: 24 | C36: num | D36: 1725 | E36: block | F36: 0 | G36: type | H36: 1 | I36: comment | K36: time(変換後) | L36: =Scores!$B$4+D36*(60000/Scores!$B$3/'避難用'!$B$1) -> 39204.545
A37: LPB | B37: 24 | C37: num | D37: 1775 | E37: block | F37: 1 | G37: type | H37: 1 | I37: comment | K37: time(変換後) | L37: =Scores!$B$4+D37*(60000/Scores!$B$3/'避難用'!$B$1) -> 40340.909
A38: LPB | B38: 24 | C38: num | D38: 1817 | E38: block | F38: 0 | G38: type | H38: 1 | I38: comment | K38: time(変換後) | L38: =Scores!$B$4+D38*(60000/Scores!$B$3/'避難用'!$B$1) -> 41295.455
... A44: LPB | B44: 24 | C44: num | D44: 1971 | E44: block | F44: 0 | G44: type | H44: 1 | I44: comment | K44: time(変換後) | L44: =Scores!$B$4+D44*(60000/Scores!$B$3/'避難用'!$B$1) -> 44795.455
A45: LPB | B45: 24 | C45: num | D45: 2053 | E45: block | F45: 2 | G45: type | H45: 1 | I45: comment | J45: A1-3 | K45: time(変換後) | L45: =Scores!$B$4+D45*(60000/Scores!$B$3/'避難用'!$B$1) -> 46659.091
A46: LPB | B46: 24 | C46: num | D46: 2099 | E46: block | F46: 3 | G46: type | H46: 1 | I46: comment | K46: time(変換後) | L46: =Scores!$B$4+D46*(60000/Scores!$B$3/'避難用'!$B$1) -> 47704.545
A47: LPB | B47: 24 | C47: num | D47: 2135 | E47: block | F47: 2 | G47: type | H47: 1 | I47: comment | K47: time(変換後) | L47: =Scores!$B$4+D47*(60000/Scores!$B$3/'避難用'!$B$1) -> 48522.727
A48: LPB | B48: 24 | C48: num | D48: 2172 | E48: block | F48: 3 | G48: type | H48: 1 | I48: comment | K48: time(変換後) | L48: =Scores!$B$4+D48*(60000/Scores!$B$3/'避難用'!$B$1) -> 49363.636
A49: LPB | B49: 24 | C49: num | D49: 2217 | E49: block | F49: 2 | G49: type | H49: 1 | I49: comment | K49: time(変換後) | L49: =Scores!$B$4+D49*(60000/Scores!$B$3/'避難用'!$B$1) -> 50386.364
A50: LPB | B50: 24 | C50: num | D50: 2253 | E50: block | F50: 3 | G50: type | H50: 1 | I50: comment | K50: time(変換後) | L50: =Scores!$B$4+D50*(60000/Scores!$B$3/'避難用'!$B$1) -> 51204.545
...
